<?xml version="1.0" encoding="utf-8"?>
<!-- This URDF was automatically created by SolidWorks to URDF Exporter! Originally created by Stephen Brawner (brawner@gmail.com) 
     Commit Version: 1.6.0-4-g7f85cfe  Build Version: 1.6.7995.38578
     For more information, please see http://wiki.ros.org/sw_urdf_exporter -->
<robot
  name="qbl">
  <link
    name="base_link">
    <inertial>
      <origin
        xyz="0.0011834 0.067737 -0.00084264"
        rpy="0 0 0" />
      <mass
        value="2.6054" />
      <inertia
        ixx="0.0028949"
        ixy="-1.3394E-05"
        ixz="-4.6804E-05"
        iyy="0.001553"
        iyz="2.5477E-05"
        izz="0.003805" />
    </inertial>
    <visual>
      <origin
        xyz="0 0 0"
        rpy="0 0 0" />
      <geometry>
        <mesh
          filename="left_meshes/base_link.STL" />
      </geometry>
      <material
        name="">
        <color
          rgba="0.52941 0.54902 0.54902 1" />
      </material>
    </visual>
    <collision>
      <origin
        xyz="0 0 0"
        rpy="0 0 0" />
      <geometry>
        <mesh
          filename="left_meshes/base_link.STL" />
      </geometry>
    </collision>
  </link>
  <link
    name="Link1">
    <inertial>
      <origin
        xyz="-0.010939 -0.0075415 0.010599"
        rpy="0 0 0" />
      <mass
        value="0.084877" />
      <inertia
        ixx="7.453E-06"
        ixy="-3.6228E-07"
        ixz="2.2145E-06"
        iyy="9.4316E-06"
        iyz="3.0013E-07"
        izz="8.5666E-06" />
    </inertial>
    <visual>
      <origin
        xyz="0 0 0"
        rpy="0 0 0" />
      <geometry>
        <mesh
          filename="left_meshes/Link1.STL" />
      </geometry>
      <material
        name="">
        <color
          rgba="0.52941 0.54902 0.54902 1" />
      </material>
    </visual>
    <collision>
      <origin
        xyz="0 0 0"
        rpy="0 0 0" />
      <geometry>
        <mesh
          filename="left_meshes/Link1.STL" />
      </geometry>
    </collision>
  </link>
  <joint
    name="J1"
    type="revolute">
    <origin
      xyz="-0.027617 0.067519 0.010096"
      rpy="0 0 -0.087266" />
    <parent
      link="base_link" />
    <child
      link="Link1" />
    <axis
      xyz="0 -1 0" />
    <limit
      lower="-0.785"
      upper="0"
      effort="0"
      velocity="0" />
  </joint>
  <link
    name="Link2">
    <inertial>
      <origin
        xyz="3.5348E-08 -0.014575 0.017417"
        rpy="0 0 0" />
      <mass
        value="0.19122" />
      <inertia
        ixx="4.6251E-05"
        ixy="1.6945E-10"
        ixz="-1.7717E-10"
        iyy="2.9221E-05"
        iyz="1.3251E-05"
        izz="2.9428E-05" />
    </inertial>
    <visual>
      <origin
        xyz="0 0 0"
        rpy="0 0 0" />
      <geometry>
        <mesh
          filename="left_meshes/Link2.STL" />
      </geometry>
      <material
        name="">
        <color
          rgba="0.52941 0.54902 0.54902 1" />
      </material>
    </visual>
    <collision>
      <origin
        xyz="0 0 0"
        rpy="0 0 0" />
      <geometry>
        <mesh
          filename="left_meshes/Link2.STL" />
      </geometry>
    </collision>
  </link>
  <joint
    name="J2"
    type="revolute">
    <origin
      xyz="-0.020804 -0.0022275 0.019453"
      rpy="-1.5708 -0.82598 0" />
    <parent
      link="Link1" />
    <child
      link="Link2" />
    <axis
      xyz="1 0 0" />
    <limit
      lower="-0.29"
      upper="0"
      effort="0"
      velocity="0" />
  </joint>
  <link
    name="Link3">
    <inertial>
      <origin
        xyz="-0.00554498401549265 -0.0149955274515526 0.0035969189079702"
        rpy="0 0 0" />
      <mass
        value="0.0765973981118237" />
      <inertia
        ixx="8.30144603842501E-06"
        ixy="-9.5356750093881E-10"
        ixz="2.55365645942459E-09"
        iyy="5.68394938581324E-06"
        iyz="1.93897381475041E-06"
        izz="6.38402311957504E-06" />
    </inertial>
    <visual>
      <origin
        xyz="0 0 0"
        rpy="0 0 0" />
      <geometry>
        <mesh
          filename="left_meshes/Link3.STL" />
      </geometry>
      <material
        name="">
        <color
          rgba="0.529411764705882 0.549019607843137 0.549019607843137 1" />
      </material>
    </visual>
    <collision>
      <origin
        xyz="0 0 0"
        rpy="0 0 0" />
      <geometry>
        <mesh
          filename="left_meshes/Link3.STL" />
      </geometry>
    </collision>
  </link>
  <joint
    name="J3"
    type="revolute">
    <origin
      xyz="0.0055478 -0.030486 0.041387"
      rpy="0 0 0" />
    <parent
      link="Link2" />
    <child
      link="Link3" />
    <axis
      xyz="1 0 0" />
    <limit
      lower="-0.44"
      upper="0"
      effort="0"
      velocity="0" />
  </joint>
  <link
    name="Link4">
    <inertial>
      <origin
        xyz="0.00536263110062123 0.015915507510902 0.00310112212569524"
        rpy="0 0 0" />
      <mass
        value="0.0683287847420413" />
      <inertia
        ixx="7.25253389599054E-06"
        ixy="-5.70124291271522E-12"
        ixz="-9.36000971588422E-13"
        iyy="2.81440005855269E-06"
        iyz="-2.68021038981231E-07"
        izz="7.37351998350572E-06" />
    </inertial>
    <visual>
      <origin
        xyz="0 0 0"
        rpy="0 0 0" />
      <geometry>
        <mesh
          filename="left_meshes/Link4.STL" />
      </geometry>
      <material
        name="">
        <color
          rgba="0.529411764705882 0.549019607843137 0.549019607843137 1" />
      </material>
    </visual>
    <collision>
      <origin
        xyz="0 0 0"
        rpy="0 0 0" />
      <geometry>
        <mesh
          filename="left_meshes/Link4.STL" />
      </geometry>
    </collision>
  </link>
  <joint
    name="J4"
    type="revolute">
    <origin
      xyz="-0.035982 0.1374 0.001"
      rpy="0 0 0" />
    <parent
      link="base_link" />
    <child
      link="Link4" />
    <axis
      xyz="-1 0 0" />
    <limit
      lower="-1.24"
      upper="0"
      effort="0"
      velocity="0" />
  </joint>
  <link
    name="Link5">
    <inertial>
      <origin
        xyz="0.00449704681207759 0.0252319167423484 0.00730236996720031"
        rpy="0 0 0" />
      <mass
        value="0.0755273947118296" />
      <inertia
        ixx="1.57108941986939E-05"
        ixy="-2.97479691158278E-09"
        ixz="-3.98319473259322E-10"
        iyy="3.22620679324468E-06"
        iyz="-3.07209826969602E-06"
        izz="1.50311395511445E-05" />
    </inertial>
    <visual>
      <origin
        xyz="0 0 0"
        rpy="0 0 0" />
      <geometry>
        <mesh
          filename="left_meshes/Link5.STL" />
      </geometry>
      <material
        name="">
        <color
          rgba="0.529411764705882 0.549019607843137 0.549019607843137 1" />
      </material>
    </visual>
    <collision>
      <origin
        xyz="0 0 0"
        rpy="0 0 0" />
      <geometry>
        <mesh
          filename="left_meshes/Link5.STL" />
      </geometry>
    </collision>
  </link>
  <joint
    name="J5"
    type="revolute">
    <origin
      xyz="0.00086299 0.03196 0.0029665"
      rpy="0 0 0" />
    <parent
      link="Link4" />
    <child
      link="Link5" />
    <axis
      xyz="-1 0 0" />
    <limit
      lower="-1.57"
      upper="0"
      effort="0"
      velocity="0" />
  </joint>
  <link
    name="Link6">
    <inertial>
      <origin
        xyz="0.0044996 0.016013 0.0025531"
        rpy="0 0 0" />
      <mass
        value="0.068329" />
      <inertia
        ixx="7.2525E-06"
        ixy="-5.6916E-12"
        ixz="-5.7717E-14"
        iyy="2.8014E-06"
        iyz="-1.1101E-07"
        izz="7.3865E-06" />
    </inertial>
    <visual>
      <origin
        xyz="0 0 0"
        rpy="0 0 0" />
      <geometry>
        <mesh
          filename="left_meshes/Link6.STL" />
      </geometry>
      <material
        name="">
        <color
          rgba="0.52941 0.54902 0.54902 1" />
      </material>
    </visual>
    <collision>
      <origin
        xyz="0 0 0"
        rpy="0 0 0" />
      <geometry>
        <mesh
          filename="left_meshes/Link6.STL" />
      </geometry>
    </collision>
  </link>
  <joint
    name="J6"
    type="revolute">
    <origin
      xyz="-0.013119 0.1374 0.001"
      rpy="0 0 0" />
    <parent
      link="base_link" />
    <child
      link="Link6" />
    <axis
      xyz="-1 0 0" />
    <limit
      lower="-1.24"
      upper="0"
      effort="0"
      velocity="0" />
  </joint>
  <link
    name="Link7">
    <inertial>
      <origin
        xyz="0.0044971 0.025545 0.0061173"
        rpy="0 0 0" />
      <mass
        value="0.075527" />
      <inertia
        ixx="1.5711E-05"
        ixy="-3.0001E-09"
        ixz="-2.5828E-10"
        iyy="2.9656E-06"
        iyz="-2.5086E-06"
        izz="1.5292E-05" />
    </inertial>
    <visual>
      <origin
        xyz="0 0 0"
        rpy="0 0 0" />
      <geometry>
        <mesh
          filename="left_meshes/Link7.STL" />
      </geometry>
      <material
        name="">
        <color
          rgba="0.52941 0.54902 0.54902 1" />
      </material>
    </visual>
    <collision>
      <origin
        xyz="0 0 0"
        rpy="0 0 0" />
      <geometry>
        <mesh
          filename="left_meshes/Link7.STL" />
      </geometry>
    </collision>
  </link>
  <joint
    name="J7"
    type="revolute">
    <origin
      xyz="0 0.032043 0.001868"
      rpy="0 0 0" />
    <parent
      link="Link6" />
    <child
      link="Link7" />
    <axis
      xyz="-1 0 0" />
    <limit
      lower="-1.57"
      upper="0"
      effort="0"
      velocity="0" />
  </joint>
  <link
    name="Link8">
    <inertial>
      <origin
        xyz="0.0044996 0.016172 0.0011738"
        rpy="0 0 0" />
      <mass
        value="0.068329" />
      <inertia
        ixx="7.2525E-06"
        ixy="-5.4925E-12"
        ixz="1.7039E-12"
        iyy="2.816E-06"
        iyz="2.8147E-07"
        izz="7.3719E-06" />
    </inertial>
    <visual>
      <origin
        xyz="0 0 0"
        rpy="0 0 0" />
      <geometry>
        <mesh
          filename="left_meshes/Link8.STL" />
      </geometry>
      <material
        name="">
        <color
          rgba="0.52941 0.54902 0.54902 1" />
      </material>
    </visual>
    <collision>
      <origin
        xyz="0 0 0"
        rpy="0 0 0" />
      <geometry>
        <mesh
          filename="left_meshes/Link8.STL" />
      </geometry>
    </collision>
  </link>
  <joint
    name="J8"
    type="revolute">
    <origin
      xyz="0.0088806 0.1374 0.001"
      rpy="0 0 0" />
    <parent
      link="base_link" />
    <child
      link="Link8" />
    <axis
      xyz="-1 0 0" />
    <limit
      lower="-1.24"
      upper="0"
      effort="0"
      velocity="0" />
  </joint>
  <link
    name="Link9">
    <inertial>
      <origin
        xyz="0.0044978 0.024578 0.0092678"
        rpy="0 0 0" />
      <mass
        value="0.075531" />
      <inertia
        ixx="1.5711E-05"
        ixy="-2.7048E-09"
        ixz="-5.3112E-10"
        iyy="3.7823E-06"
        iyz="-3.9614E-06"
        izz="1.4476E-05" />
    </inertial>
    <visual>
      <origin
        xyz="0 0 0"
        rpy="0 0 0" />
      <geometry>
        <mesh
          filename="left_meshes/Link9.STL" />
      </geometry>
      <material
        name="">
        <color
          rgba="0.52941 0.54902 0.54902 1" />
      </material>
    </visual>
    <collision>
      <origin
        xyz="0 0 0"
        rpy="0 0 0" />
      <geometry>
        <mesh
          filename="left_meshes/Link9.STL" />
      </geometry>
    </collision>
  </link>
  <joint
    name="J9"
    type="revolute">
    <origin
      xyz="0 0.032085 -0.00088032"
      rpy="0 0 0" />
    <parent
      link="Link8" />
    <child
      link="Link9" />
    <axis
      xyz="-1 0 0" />
    <limit
      lower="-1.57"
      upper="0"
      effort="0"
      velocity="0" />
  </joint>
  <link
    name="Link10">
    <inertial>
      <origin
        xyz="0.0053626 0.016172 0.0011738"
        rpy="0 0 0" />
      <mass
        value="0.068329" />
      <inertia
        ixx="7.2525E-06"
        ixy="-5.4925E-12"
        ixz="1.7039E-12"
        iyy="2.816E-06"
        iyz="2.8147E-07"
        izz="7.3719E-06" />
    </inertial>
    <visual>
      <origin
        xyz="0 0 0"
        rpy="0 0 0" />
      <geometry>
        <mesh
          filename="left_meshes/Link10.STL" />
      </geometry>
      <material
        name="">
        <color
          rgba="0.52941 0.54902 0.54902 1" />
      </material>
    </visual>
    <collision>
      <origin
        xyz="0 0 0"
        rpy="0 0 0" />
      <geometry>
        <mesh
          filename="left_meshes/Link10.STL" />
      </geometry>
    </collision>
  </link>
  <joint
    name="J10"
    type="revolute">
    <origin
      xyz="0.030018 0.13417 0.001"
      rpy="0 0 0" />
    <parent
      link="base_link" />
    <child
      link="Link10" />
    <axis
      xyz="-1 0 0" />
    <limit
      lower="-1.24"
      upper="0"
      effort="0"
      velocity="0" />
  </joint>
  <link
    name="Link11">
    <inertial>
      <origin
        xyz="0.0044978 0.024578 0.0092678"
        rpy="0 0 0" />
      <mass
        value="0.075531" />
      <inertia
        ixx="1.5711E-05"
        ixy="-2.7048E-09"
        ixz="-5.3112E-10"
        iyy="3.7823E-06"
        iyz="-3.9614E-06"
        izz="1.4476E-05" />
    </inertial>
    <visual>
      <origin
        xyz="0 0 0"
        rpy="0 0 0" />
      <geometry>
        <mesh
          filename="left_meshes/Link11.STL" />
      </geometry>
      <material
        name="">
        <color
          rgba="0.52941 0.54902 0.54902 1" />
      </material>
    </visual>
    <collision>
      <origin
        xyz="0 0 0"
        rpy="0 0 0" />
      <geometry>
        <mesh
          filename="left_meshes/Link11.STL" />
      </geometry>
    </collision>
  </link>
  <joint
    name="J11"
    type="revolute">
    <origin
      xyz="0.00086299 0.032085 -0.00088032"
      rpy="0 0 0" />
    <parent
      link="Link10" />
    <child
      link="Link11" />
    <axis
      xyz="-1 0 0" />
    <limit
      lower="-1.57"
      upper="0"
      effort="0"
      velocity="0" />
  </joint>
</robot>
