<?xml version='1.0' encoding='utf-8'?>
<robot name="qbr">
  <link name="base_link">
    <inertial>
      <origin xyz="-0.00119902400080689 0.0676395118380097 -0.000831468763240618" rpy="0 0 0" />
      <mass value="2.61841951961561" />
      <inertia ixx="0.00289488464735745" ixy="1.26632522214081E-05" ixz="4.75779358553846E-05" iyy="0.0015541400089684" iyz="2.51442141340795E-05" izz="0.00380659471612325" />
    </inertial>
    <visual>
      <origin xyz="0 0 0" rpy="0 0 0" />
      <geometry>
        <mesh filename="right_meshes/base_link.STL" />
      </geometry>
      <material name="">
        <color rgba="0.529411764705882 0.549019607843137 0.549019607843137 1" />
      </material>
    </visual>
    <collision>
      <origin xyz="0 0 0" rpy="0 0 0" />
      <geometry>
        <mesh filename="right_meshes/base_link.STL" />
      </geometry>
    </collision>
  </link>
  <link name="link1">
    <inertial>
      <origin xyz="0.0137751250378393 -0.00981394991394148 0.00208430495133732" rpy="0 0 0" />
      <mass value="0.0848759840699757" />
      <inertia ixx="6.02792303641558E-06" ixy="4.58047907735606E-07" ixz="-1.13414482822443E-06" iyy="9.43150541499264E-06" iyz="1.07407363059388E-07" izz="9.99149179527929E-06" />
    </inertial>
    <visual>
      <origin xyz="0 0 0" rpy="0 0 0" />
      <geometry>
        <mesh filename="right_meshes/link1.STL" />
      </geometry>
      <material name="">
        <color rgba="0.529411764705882 0.549019607843137 0.549019607843137 1" />
      </material>
    </visual>
    <collision>
      <origin xyz="0 0 0" rpy="0 0 0" />
      <geometry>
        <mesh filename="right_meshes/link1.STL" />
      </geometry>
    </collision>
  </link>
  <joint name="j1" type="revolute">
    <origin xyz="0.028693 0.069894 0.010325" rpy="0 0 0.087266" />
    <parent link="base_link" />
    <child link="link1" />
    <axis xyz="0 1 0" />
    <limit lower="-1.785" upper="0" effort="0" velocity="0" />
  </joint>
  <link name="link2">
    <inertial>
      <origin xyz="4.36100697220887E-09 0.0183171211967979 -0.012870354643197" rpy="0 0 0" />
      <mass value="0.189071895133877" />
      <inertia ixx="4.62451218821649E-05" ixy="1.70090875141461E-10" ixz="-1.79647819838937E-10" iyy="2.71230540243915E-05" iyz="1.30744554320643E-05" izz="3.14501850290832E-05" />
    </inertial>
    <visual>
      <origin xyz="0 0 0" rpy="0 0 0" />
      <geometry>
        <mesh filename="right_meshes/link2.STL" />
      </geometry>
      <material name="">
        <color rgba="0.529411764705882 0.549019607843137 0.549019607843137 1" />
      </material>
    </visual>
    <collision>
      <origin xyz="0 0 0" rpy="0 0 0" />
      <geometry>
        <mesh filename="right_meshes/link2.STL" />
      </geometry>
    </collision>
  </link>
  <joint name="j2" type="revolute">
    <origin xyz="0.02679 -0.0045 0.0045976" rpy="3.0557 -1.3935 3.1416" />
    <parent link="link1" />
    <child link="link2" />
    <axis xyz="1 0 0" />
    <limit lower="0" upper="0.29" effort="0" velocity="0" />
  </joint>
  <link name="link3">
    <inertial>
      <origin xyz="-0.00555064313303445 0.00539090806696246 -0.0144478834389504" rpy="0 0 0" />
      <mass value="0.0765978194144121" />
      <inertia ixx="8.30143631907092E-06" ixy="-2.64543837885093E-09" ixz="6.33140406065459E-10" iyy="5.90636128499543E-06" iyz="1.96617508560125E-06" izz="6.16162484246875E-06" />
    </inertial>
    <visual>
      <origin xyz="0 0 0" rpy="0 0 0" />
      <geometry>
        <mesh filename="right_meshes/link3.STL" />
      </geometry>
      <material name="">
        <color rgba="0.529411764705882 0.549019607843137 0.549019607843137 1" />
      </material>
    </visual>
    <collision>
      <origin xyz="0 0 0" rpy="0 0 0" />
      <geometry>
        <mesh filename="right_meshes/link3.STL" />
      </geometry>
    </collision>
  </link>
  <joint name="j3" type="revolute">
    <origin xyz="0.0055478 0.0413 -0.024172" rpy="0 0 0" />
    <parent link="link2" />
    <child link="link3" />
    <axis xyz="1 0 0" />
    <limit lower="0" upper="0.44" effort="0" velocity="0" />
    <mimic joint="j2" multiplier="1.517" offset="0" />
  </joint>
  <link name="link4">
    <inertial>
      <origin xyz="-0.0036569973005798 0.0162113209076923 0.000273547127676674" rpy="0 0 0" />
      <mass value="0.0686348714224919" />
      <inertia ixx="7.33254847238726E-06" ixy="-2.66340785344831E-12" ixz="1.08765083632757E-12" iyy="2.87970755794507E-06" iyz="5.37142487415021E-07" izz="7.422847187087E-06" />
    </inertial>
    <visual>
      <origin xyz="0 0 0" rpy="0 0 0" />
      <geometry>
        <mesh filename="right_meshes/link4.STL" />
      </geometry>
      <material name="">
        <color rgba="0.529411764705882 0.549019607843137 0.549019607843137 1" />
      </material>
    </visual>
    <collision>
      <origin xyz="0 0 0" rpy="0 0 0" />
      <geometry>
        <mesh filename="right_meshes/link4.STL" />
      </geometry>
    </collision>
  </link>
  <joint name="j4" type="revolute">
    <origin xyz="0.034276 0.1374 0.001" rpy="0 0 0" />
    <parent link="base_link" />
    <child link="link4" />
    <axis xyz="-1 0 0" />
    <limit lower="-1.24" upper="0" effort="0" velocity="0" />
  </joint>
  <link name="link5">
    <inertial>
      <origin xyz="-0.00450223853979242 0.0245775687164807 0.00926785909974535" rpy="0 0 0" />
      <mass value="0.0755292904950472" />
      <inertia ixx="1.57108591312927E-05" ixy="-2.65891509368178E-09" ixz="-5.06696550628499E-10" iyy="3.78223232864861E-06" iyz="-3.96130529426087E-06" izz="1.44759601190385E-05" />
    </inertial>
    <visual>
      <origin xyz="0 0 0" rpy="0 0 0" />
      <geometry>
        <mesh filename="right_meshes/link5.STL" />
      </geometry>
      <material name="">
        <color rgba="0.529411764705882 0.549019607843137 0.549019607843137 1" />
      </material>
    </visual>
    <collision>
      <origin xyz="0 0 0" rpy="0 0 0" />
      <geometry>
        <mesh filename="right_meshes/link5.STL" />
      </geometry>
    </collision>
  </link>
  <joint name="j5" type="revolute">
    <origin xyz="0.00084336 0.031988 -0.0026473" rpy="0 0 0" />
    <parent link="link4" />
    <child link="link5" />
    <axis xyz="-1 0 0" />
    <limit lower="-1.147" upper="0" effort="0" velocity="0" />
    <mimic joint="j4" multiplier="0.925" offset="0" />
  </joint>
  <link name="link6">
    <inertial>
      <origin xyz="-0.00365699730057982 0.0162113209076926 0.00027354712767666" rpy="0 0 0" />
      <mass value="0.0686348714224907" />
      <inertia ixx="7.33254847238703E-06" ixy="-2.66340787168868E-12" ixz="1.08765081322438E-12" iyy="2.87970755794502E-06" iyz="5.37142487415025E-07" izz="7.42284718708672E-06" />
    </inertial>
    <visual>
      <origin xyz="0 0 0" rpy="0 0 0" />
      <geometry>
        <mesh filename="right_meshes/link6.STL" />
      </geometry>
      <material name="">
        <color rgba="0.529411764705882 0.549019607843137 0.549019607843137 1" />
      </material>
    </visual>
    <collision>
      <origin xyz="0 0 0" rpy="0 0 0" />
      <geometry>
        <mesh filename="right_meshes/link6.STL" />
      </geometry>
    </collision>
  </link>
  <joint name="j6" type="revolute">
    <origin xyz="0.012276 0.14055 0.001" rpy="0 0 0" />
    <parent link="base_link" />
    <child link="link6" />
    <axis xyz="-1 0 0" />
    <limit lower="-1.24" upper="0" effort="0" velocity="0" />
  </joint>
  <link name="link7">
    <inertial>
      <origin xyz="-0.00365887353581443 0.0268852930825247 0.00907687418344099" rpy="0 0 0" />
      <mass value="0.0755292952305594" />
      <inertia ixx="1.57108601660693E-05" ixy="-2.65847990684081E-09" ixz="-5.06510838631664E-10" iyy="3.78223268736312E-06" iyz="-3.96130566158398E-06" izz="1.44759612204894E-05" />
    </inertial>
    <visual>
      <origin xyz="0 0 0" rpy="0 0 0" />
      <geometry>
        <mesh filename="right_meshes/link7.STL" />
      </geometry>
      <material name="">
        <color rgba="0.529411764705882 0.549019607843137 0.549019607843137 1" />
      </material>
    </visual>
    <collision>
      <origin xyz="0 0 0" rpy="0 0 0" />
      <geometry>
        <mesh filename="right_meshes/link7.STL" />
      </geometry>
    </collision>
  </link>
  <joint name="j7" type="revolute">
    <origin xyz="0 0.02968 -0.0024563" rpy="0 0 0" />
    <parent link="link6" />
    <child link="link7" />
    <axis xyz="-1 0 0" />
    <limit lower="-1.147" upper="0" effort="0" velocity="0" />
    <mimic joint="j6" multiplier="0.925" offset="0" />
  </joint>
  <link name="link8">
    <inertial>
      <origin xyz="-0.00365699730057996 0.0162113209076925 0.000273547127676729" rpy="0 0 0" />
      <mass value="0.0686348714224909" />
      <inertia ixx="7.33254847238706E-06" ixy="-2.66340798155937E-12" ixz="1.08765082198048E-12" iyy="2.87970755794502E-06" iyz="5.37142487415066E-07" izz="7.42284718708676E-06" />
    </inertial>
    <visual>
      <origin xyz="0 0 0" rpy="0 0 0" />
      <geometry>
        <mesh filename="right_meshes/link8.STL" />
      </geometry>
      <material name="">
        <color rgba="0.529411764705882 0.549019607843137 0.549019607843137 1" />
      </material>
    </visual>
    <collision>
      <origin xyz="0 0 0" rpy="0 0 0" />
      <geometry>
        <mesh filename="right_meshes/link8.STL" />
      </geometry>
    </collision>
  </link>
  <joint name="j8" type="revolute">
    <origin xyz="-0.009724 0.1374 0.001" rpy="0 0 0" />
    <parent link="base_link" />
    <child link="link8" />
    <axis xyz="-1 0 0" />
    <limit lower="-1.24" upper="0" effort="0" velocity="0" />
  </joint>
  <link name="link9">
    <inertial>
      <origin xyz="-0.00365887394452614 0.0268852939054231 0.00907687452350932" rpy="0 0 0" />
      <mass value="0.0755292904717439" />
      <inertia ixx="1.57108591192926E-05" ixy="-2.6589152266971E-09" ixz="-5.06696620209176E-10" iyy="3.78223232752807E-06" iyz="-3.96130529054741E-06" izz="1.44759601085164E-05" />
    </inertial>
    <visual>
      <origin xyz="0 0 0" rpy="0 0 0" />
      <geometry>
        <mesh filename="right_meshes/link9.STL" />
      </geometry>
      <material name="">
        <color rgba="0.529411764705882 0.549019607843137 0.549019607843137 1" />
      </material>
    </visual>
    <collision>
      <origin xyz="0 0 0" rpy="0 0 0" />
      <geometry>
        <mesh filename="right_meshes/link9.STL" />
      </geometry>
    </collision>
  </link>
  <joint name="j9" type="revolute">
    <origin xyz="0 0.02968 -0.0024563" rpy="0 0 0" />
    <parent link="link8" />
    <child link="link9" />
    <axis xyz="-1 0 0" />
    <limit lower="-1.147" upper="0" effort="0" velocity="0" />
    <mimic joint="j8" multiplier="0.925" offset="0" />
  </joint>
  <link name="link10">
    <inertial>
      <origin xyz="-0.0036569973005798 0.0162113209076923 0.000273547127676674" rpy="0 0 0" />
      <mass value="0.0686348714224923" />
      <inertia ixx="7.33254847238732E-06" ixy="-2.66340783682772E-12" ixz="1.08765084134209E-12" iyy="2.87970755794509E-06" iyz="5.37142487415014E-07" izz="7.42284718708707E-06" />
    </inertial>
    <visual>
      <origin xyz="0 0 0" rpy="0 0 0" />
      <geometry>
        <mesh filename="right_meshes/link10.STL" />
      </geometry>
      <material name="">
        <color rgba="0.529411764705882 0.549019607843137 0.549019607843137 1" />
      </material>
    </visual>
    <collision>
      <origin xyz="0 0 0" rpy="0 0 0" />
      <geometry>
        <mesh filename="right_meshes/link10.STL" />
      </geometry>
    </collision>
  </link>
  <joint name="j10" type="revolute">
    <origin xyz="-0.031724 0.13417 0.001" rpy="0 0 0" />
    <parent link="base_link" />
    <child link="link10" />
    <axis xyz="-1 0 0" />
    <limit lower="-1.24" upper="0" effort="0" velocity="0" />
  </joint>
  <link name="link11">
    <inertial>
      <origin xyz="-0.00450223813308796 0.0245775695404106 0.00926785944008141" rpy="0 0 0" />
      <mass value="0.0755292857716501" />
      <inertia ixx="1.57108580998035E-05" ixy="-2.6584823064413E-09" ixz="-5.06511787908576E-10" iyy="3.78223197131172E-06" iyz="-3.96130492810724E-06" izz="1.44759590213488E-05" />
    </inertial>
    <visual>
      <origin xyz="0 0 0" rpy="0 0 0" />
      <geometry>
        <mesh filename="right_meshes/link11.STL" />
      </geometry>
      <material name="">
        <color rgba="0.529411764705882 0.549019607843137 0.549019607843137 1" />
      </material>
    </visual>
    <collision>
      <origin xyz="0 0 0" rpy="0 0 0" />
      <geometry>
        <mesh filename="right_meshes/link11.STL" />
      </geometry>
    </collision>
  </link>
  <joint name="j11" type="revolute">
    <origin xyz="0.00084336 0.031988 -0.0026473" rpy="0 0 0" />
    <parent link="link10" />
    <child link="link11" />
    <axis xyz="-1 0 0" />
    <limit lower="-1.147" upper="0" effort="0" velocity="0" />
    <mimic joint="j10" multiplier="0.925" offset="0" />
  </joint>

<!-- virtual thumb_tip -->
<link name="thumb_tip">
  <!-- visualize -->
  <!-- <visual>
    <geometry>
      <sphere radius="0.002"/>
    </geometry>
    <material name="tip_color">
      <color rgba="1 0 0 1"/>
    </material>
  </visual> -->
</link>

<!-- fixed joint -->
<joint name="j3_tip" type="fixed">
  <parent link="link3"/>
  <child link="thumb_tip"/>
  <origin xyz="-0.00745 0.01511 -0.02967" rpy="0 0 0"/>
</joint>

<!-- virtual index_tip -->
<link name="index_tip">
  <!-- visualize -->
  <!-- <visual>
    <geometry>
      <sphere radius="0.002"/>
    </geometry>
    <material name="tip_color">
      <color rgba="1 0 0 1"/>
    </material>
  </visual> -->
</link>

<!-- fixed joint -->
<joint name="j5_tip" type="fixed">
  <parent link="link5"/>
  <child link="index_tip"/>
  <origin xyz="-0.005 0.0506 0.01942" rpy="0 0 0"/>
</joint>

<!-- virtual middle_tip -->
<link name="middle_tip">
  <!-- visualize -->
  <!-- <visual>
    <geometry>
      <sphere radius="0.002"/>
    </geometry>
    <material name="tip_color">
      <color rgba="1 0 0 1"/>
    </material>
  </visual> -->
</link>

<!-- fixed joint -->
<joint name="j7_tip" type="fixed">
  <parent link="link7"/>
  <child link="middle_tip"/>
  <origin xyz="-0.005 0.0506 0.01942" rpy="0 0 0"/>
</joint>

<!-- virtual ring_tip -->
<link name="ring_tip">
  <!-- visualize -->
  <!-- <visual>
    <geometry>
      <sphere radius="0.002"/>
    </geometry>
    <material name="tip_color">
      <color rgba="1 0 0 1"/>
    </material>
  </visual> -->
</link>

<!-- fixed joint -->
<joint name="j9_tip" type="fixed">
  <parent link="link9"/>
  <child link="ring_tip"/>
  <origin xyz="-0.005 0.0506 0.01942" rpy="0 0 0"/>
</joint>

<!-- virtual pinky_tip -->
<link name="pinky_tip">
  <!-- visualize -->
  <!-- <visual>
    <geometry>
      <sphere radius="0.002"/>
    </geometry>
    <material name="tip_color">
      <color rgba="1 0 0 1"/>
    </material>
  </visual> -->
</link>

<!-- fixed joint -->
<joint name="j11_tip" type="fixed">
  <parent link="link11"/>
  <child link="pinky_tip"/>
  <origin xyz="-0.005 0.0506 0.01942" rpy="0 0 0"/>
</joint>

<link name="wrist" /><joint name="wrist_to_base" type="fixed"><origin xyz="0 0 0" rpy="1.57079632679 0 1.57079632679" /><parent link="wrist" /><child link="base_link" /></joint></robot>